Workbook

Sheet Запчасти
A1: Артикул | B1: Наименование | C1: Производитель | D1: Подходит к авто | E1: Категория | F1: Дата поступления | G1: Закупочная цена | H1: Цена продажи | I1: Поступило | J1: Продано | K1: Остаток | L1: Всего на сумму | M1: Выручка | N1: Себестоимость проданного | O1: Прибыль | P1: Комментарий | Q1: Артикул (текст) | R1: autogur73.ru, RUB | S1: chipdip.kz, KZT | T1: uaz.store, RUB | U1: metalpart.ru, RUB | V1: detaliuaz.ru, RUB | W1: vta-gaz.ru, RUB | X1: spectuninguaz.ru, RUB | Y1: 4uaz.ru, RUB | Z1: Kaspi, KZT | AA1: Ozon, KZT | AB1: Найдено цен | AC1: Средняя цена рынка, ₸ | AD1: Своя наценка, % | AE1: Наценка итого, % | AF1: Новая цена, ₸ | AG1: Текущая цена к рынку | AH1: Ссылки / заметки по ценам
A2: 4693501070 | B2: Задний тормозной барабан | C2: Уаз | D2: УАЗ Буханка | E2: Тормоза | H2: 20000 | I2: 13 | K2: =I2-J2 -> 13 | L2: =K2*H2 -> 260000 | M2: =IF(A2="","",H2*J2) -> 0 | N2: =IF(A2="","",G2*J2) -> 0 | O2: =IF(A2="","",M2-N2) -> 0 | Q2: 4693501070 | AB2: =SUMPRODUCT(--(R2:AA2>0),'Настройки цен'!$B$12:$K$12) -> 0 | AC2: =IF(AB2=0,"",SUMPRODUCT(R2:AA2,'Настройки цен'!$B$11:$K$11,'Настройки цен'!$B$12:$K$12)/AB2) | AE2: =IF(AD2<>"",AD2,IFERROR(IF(INDEX('Настройки цен'!$B$17:$B$24,MATCH(E2,'Настройки цен'!$A$17:$A$24,0))="",'Настройки цен'!$B$5,INDEX('Настройки цен'!$B$17:$B$24,MATCH(E2,'Настройки цен'!$A$17:$A$24,0))),'Настройки цен'!$B$5)) -> 0 | AF2: =IF(AC2="","",ROUND(AC2*(1+AE2)/'Настройки цен'!$B$6,0)*'Настройки цен'!$B$6) | AG2: =IF(OR(AC2="",H2=""),"",H2/AC2-1) | AH2: Не в списке сайтов, для справки: АДС ~3 200 ₽, оригинал УАЗ ~5 000–6 000 ₽ (sparox.ru, uazist.ru). Цена сильно зависит от производителя.
A3: 37413502013 | B3: Тормозной щит | C3: УАЗ | D3: УАЗ Буханка | E3: Тормоза | H3: 15000 | I3: 4 | K3: =I3-J3 -> 4 | L3: =K3*H3 -> 60000 | M3: =IF(A3="","",H3*J3) -> 0 | N3: =IF(A3="","",G3*J3) -> 0 | O3: =IF(A3="","",M3-N3) -> 0 | Q3: 37413502013 | AB3: =SUMPRODUCT(--(R3:AA3>0),'Настройки цен'!$B$12:$K$12) -> 0 | AC3: =IF(AB3=0,"",SUMPRODUCT(R3:AA3,'Настройки цен'!$B$11:$K$11,'Настройки цен'!$B$12:$K$12)/AB3) | AE3: =IF(AD3<>"",AD3,IFERROR(IF(INDEX('Настройки цен'!$B$17:$B$24,MATCH(E3,'Настройки цен'!$A$17:$A$24,0))="",'Настройки цен'!$B$5,INDEX('Настройки цен'!$B$17:$B$24,MATCH(E3,'Настройки цен'!$A$17:$A$24,0))),'Настройки цен'!$B$5)) -> 0 | AF3: =IF(AC3="","",ROUND(AC3*(1+AE3)/'Настройки цен'!$B$6,0)*'Настройки цен'!$B$6) | AG3: =IF(OR(AC3="",H3=""),"",H3/AC3-1)
A4: 316000350108400 | B4: Щиток тормозного диска | C4: УАЗ | D4: УАЗ Буханка | E4: Тормоза | H4: 4000 | I4: 18 | K4: =I4-J4 -> 18 | L4: =K4*H4 -> 72000 | M4: =IF(A4="","",H4*J4) -> 0 | N4: =IF(A4="","",G4*J4) -> 0 | O4: =IF(A4="","",M4-N4) -> 0 | Q4: 316000350108400 | AB4: =SUMPRODUCT(--(R4:AA4>0),'Настройки цен'!$B$12:$K$12) -> 0 | AC4: =IF(AB4=0,"",SUMPRODUCT(R4:AA4,'Настройки цен'!$B$11:$K$11,'Настройки цен'!$B$12:$K$12)/AB4) | AE4: =IF(AD4<>"",AD4,IFERROR(IF(INDEX('Настройки цен'!$B$17:$B$24,MATCH(E4,'Настройки цен'!$A$17:$A$24,0))="",'Настройки цен'!$B$5,INDEX('Настройки цен'!$B$17:$B$24,MATCH(E4,'Настройки цен'!$A$17:$A$24,0))),'Настройки цен'!$B$5)) -> 0 | AF4: =IF(AC4="","",ROUND(AC4*(1+AE4)/'Настройки цен'!$B$6,0)*'Настройки цен'!$B$6) | AG4: =IF(OR(AC4="",H4=""),"",H4/AC4-1)
A5: 31603501014 | B5: Тормозной суппорт УАЗ | D5: УАЗ Буханка | E5: Тормоза | H5: 45000 | I5: 11 | K5: =I5-J5 -> 11 | L5: =K5*H5 -> 495000 | M5: =IF(A5="","",H5*J5) -> 0 | N5: =IF(A5="","",G5*J5) -> 0 | O5: =IF(A5="","",M5-N5) -> 0 | Q5: 31603501014 | V5: 8429 | AB5: =SUMPRODUCT(--(R5:AA5>0),'Настройки цен'!$B$12:$K$12) -> 1 | AC5: =IF(AB5=0,"",SUMPRODUCT(R5:AA5,'Настройки цен'!$B$11:$K$11,'Настройки цен'!$B$12:$K$12)/AB5) -> 44673.7 | AE5: =IF(AD5<>"",AD5,IFERROR(IF(INDEX('Настройки цен'!$B$17:$B$24,MATCH(E5,'Настройки цен'!$A$17:$A$24,0))="",'Настройки цен'!$B$5,INDEX('Настройки цен'!$B$17:$B$24,MATCH(E5,'Настройки цен'!$A$17:$A$24,0))),'Настройки цен'!$B$5)) -> 0 | AF5: =IF(AC5="","",ROUND(AC5*(1+AE5)/'Настройки цен'!$B$6,0)*'Настройки цен'!$B$6) -> 44700 | AG5: =IF(OR(AC5="",H5=""),"",H5/AC5-1) -> 0.0073040738 | AH5: detaliuaz.ru: суппорт УАЗ-3160 левый 8 429 ₽ (правый 9 357 ₽). ВНИМАНИЕ: по каталогам 3163-3501014 — это скоба суппорта, а не суппорт. Сверить деталь.
A6: 3160350107602 | B6: Тормозной диск | D6: УАЗ Буханка | E6: Тормоза | H6: 15000 | I6: 5 | K6: =I6-J6 -> 5 | L6: =K6*H6 -> 75000 | M6: =IF(A6="","",H6*J6) -> 0 | N6: =IF(A6="","",G6*J6) -> 0 | O6: =IF(A6="","",M6-N6) -> 0 | Q6: 3160350107602 | AB6: =SUMPRODUCT(--(R6:AA6>0),'Настройки цен'!$B$12:$K$12) -> 0 | AC6: =IF(AB6=0,"",SUMPRODUCT(R6:AA6,'Настройки цен'!$B$11:$K$11,'Настройки цен'!$B$12:$K$12)/AB6) | AE6: =IF(AD6<>"",AD6,IFERROR(IF(INDEX('Настройки цен'!$B$17:$B$24,MATCH(E6,'Настройки цен'!$A$17:$A$24,0))="",'Настройки цен'!$B$5,INDEX('Настройки цен'!$B$17:$B$24,MATCH(E6,'Настройки цен'!$A$17:$A$24,0))),'Настройки цен'!$B$5)) -> 0 | AF6: =IF(AC6="","",ROUND(AC6*(1+AE6)/'Настройки цен'!$B$6,0)*'Настройки цен'!$B$6) | AG6: =IF(OR(AC6="",H6=""),"",H6/AC6-1)
A7: 220600350209110 | B7: Задние тормозные колодки | D7: УАЗ Буханка | E7: Тормоза | H7: 5000 | I7: 49 | K7: =I7-J7 -> 49 | L7: =K7*H7 -> 245000 | M7: =IF(A7="","",H7*J7) -> 0 | N7: =IF(A7="","",G7*J7) -> 0 | O7: =IF(A7="","",M7-N7) -> 0 | Q7: 220600350209110 | AB7: =SUMPRODUCT(--(R7:AA7>0),'Настройки цен'!$B$12:$K$12) -> 0 | AC7: =IF(AB7=0,"",SUMPRODUCT(R7:AA7,'Настройки цен'!$B$11:$K$11,'Настройки цен'!$B$12:$K$12)/AB7) | AE7: =IF(AD7<>"",AD7,IFERROR(IF(INDEX('Настройки цен'!$B$17:$B$24,MATCH(E7,'Настройки цен'!$A$17:$A$24,0))="",'Настройки цен'!$B$5,INDEX('Настройки цен'!$B$17:$B$24,MATCH(E7,'Настройки цен'!$A$17:$A$24,0))),'Настройки цен'!$B$5)) -> 0 | AF7: =IF(AC7="","",ROUND(AC7*(1+AE7)/'Настройки цен'!$B$6,0)*'Настройки цен'!$B$6) | AG7: =IF(OR(AC7="",H7=""),"",H7/AC7-1)
A8: 316300350108805 | B8: Дисковые колодки тормозные | D8: УАЗ Буханка | E8: Тормоза | H8: 8000 | I8: 9 | K8: =I8-J8 -> 9 | L8: =K8*H8 -> 72000 | M8: =IF(A8="","",H8*J8) -> 0 | N8: =IF(A8="","",G8*J8) -> 0 | O8: =IF(A8="","",M8-N8) -> 0 | Q8: 316300350108805 | AB8: =SUMPRODUCT(--(R8:AA8>0),'Настройки цен'!$B$12:$K$12) -> 0 | AC8: =IF(AB8=0,"",SUMPRODUCT(R8:AA8,'Настройки цен'!$B$11:$K$11,'Настройки цен'!$B$12:$K$12)/AB8) | AE8: =IF(AD8<>"",AD8,IFERROR(IF(INDEX('Настройки цен'!$B$17:$B$24,MATCH(E8,'Настройки цен'!$A$17:$A$24,0))="",'Настройки цен'!$B$5,INDEX('Настройки цен'!$B$17:$B$24,MATCH(E8,'Настройки цен'!$A$17:$A$24,0))),'Настройки цен'!$B$5)) -> 0 | AF8: =IF(AC8="","",ROUND(AC8*(1+AE8)/'Настройки цен'!$B$6,0)*'Настройки цен'!$B$6) | AG8: =IF(OR(AC8="",H8=""),"",H8/AC8-1)
A9: 31632304019 | B9: Ремкомплект шкворня моста спайсер | D9: УАЗ Буханка | E9: Подвеска | H9: 15000 | I9: 5 | K9: =I9-J9 -> 5 | L9: =K9*H9 -> 75000 | M9: =IF(A9="","",H9*J9) -> 0 | N9: =IF(A9="","",G9*J9) -> 0 | O9: =IF(A9="","",M9-N9) -> 0 | Q9: 31632304019 | AB9: =SUMPRODUCT(--(R9:AA9>0),'Настройки цен'!$B$12:$K$12) -> 0 | AC9: =IF(AB9=0,"",SUMPRODUCT(R9:AA9,'Настройки цен'!$B$11:$K$11,'Настройки цен'!$B$12:$K$12)/AB9) | AE9: =IF(AD9<>"",AD9,IFERROR(IF(INDEX('Настройки цен'!$B$17:$B$24,MATCH(E9,'Настройки цен'!$A$17:$A$24,0))="",'Настройки цен'!$B$5,INDEX('Настройки цен'!$B$17:$B$24,MATCH(E9,'Настройки цен'!$A$17:$A$24,0))),'Настройки цен'!$B$5)) -> 0 | AF9: =IF(AC9="","",ROUND(AC9*(1+AE9)/'Настройки цен'!$B$6,0)*'Настройки цен'!$B$6) | AG9: =IF(OR(AC9="",H9=""),"",H9/AC9-1)
A10: 315120230440001 | B10: Хабы оригинал (комплект) | D10: УАЗ | E10: Подвеска | H10: 50000 | I10: 1 | K10: =I10-J10 -> 1 | L10: =K10*H10 -> 50000 | M10: =IF(A10="","",H10*J10) -> 0 | N10: =IF(A10="","",G10*J10) -> 0 | O10: =IF(A10="","",M10-N10) -> 0 | Q10: 315120230440001 | AB10: =SUMPRODUCT(--(R10:AA10>0),'Настройки цен'!$B$12:$K$12) -> 0 | AC10: =IF(AB10=0,"",SUMPRODUCT(R10:AA10,'Настройки цен'!$B$11:$K$11,'Настройки цен'!$B$12:$K$12)/AB10) | AE10: =IF(AD10<>"",AD10,IFERROR(IF(INDEX('Настройки цен'!$B$17:$B$24,MATCH(E10,'Настройки цен'!$A$17:$A$24,0))="",'Настройки цен'!$B$5,INDEX('Настройки цен'!$B$17:$B$24,MATCH(E10,'Настройки цен'!$A$17:$A$24,0))),'Настройки цен'!$B$5)) -> 0 | AF10: =IF(AC10="","",ROUND(AC10*(1+AE10)/'Настройки цен'!$B$6,0)*'Настройки цен'!$B$6) | AG10: =IF(OR(AC10="",H10=""),"",H10/AC10-1)
B11: Ремкомплект поворотного кулака Хантер | D11: УАЗ | E11: Подвеска | H11: 5000 | I11: 16 | K11: =I11-J11 -> 16 | L11: =K11*H11 -> 80000 | M11: =IF(A11="","",H11*J11) | N11: =IF(A11="","",G11*J11) | O11: =IF(A11="","",M11-N11) | AB11: =SUMPRODUCT(--(R11:AA11>0),'Настройки цен'!$B$12:$K$12) -> 0 | AC11: =IF(AB11=0,"",SUMPRODUCT(R11:AA11,'Настройки цен'!$B$11:$K$11,'Настройки цен'!$B$12:$K$12)/AB11) | AE11: =IF(AD11<>"",AD11,IFERROR(IF(INDEX('Настройки цен'!$B$17:$B$24,MATCH(E11,'Настройки цен'!$A$17:$A$24,0))="",'Настройки цен'!$B$5,INDEX('Настройки цен'!$B$17:$B$24,MATCH(E11,'Настройки цен'!$A$17:$A$24,0))),'Настройки цен'!$B$5)) -> 0 | AF11: =IF(AC11="","",ROUND(AC11*(1+AE11)/'Настройки цен'!$B$6,0)*'Настройки цен'!$B$6) | AG11: =IF(OR(AC11="",H11=""),"",H11/AC11-1)
B12: Чашки листа рессоры + заклепки | D12: Уаз | E12: Подвеска | H12: 10000 | I12: 50 | K12: =I12-J12 -> 50 | L12: =K12*H12 -> 500000 | M12: =IF(A12="","",H12*J12) | N12: =IF(A12="","",G12*J12) | O12: =IF(A12="","",M12-N12) | AB12: =SUMPRODUCT(--(R12:AA12>0),'Настройки цен'!$B$12:$K$12) -> 0 | AC12: =IF(AB12=0,"",SUMPRODUCT(R12:AA12,'Настройки цен'!$B$11:$K$11,'Настройки цен'!$B$12:$K$12)/AB12) | AE12: =IF(AD12<>"",AD12,IFERROR(IF(INDEX('Настройки цен'!$B$17:$B$24,MATCH(E12,'Настройки цен'!$A$17:$A$24,0))="",'Настройки цен'!$B$5,INDEX('Настройки цен'!$B$17:$B$24,MATCH(E12,'Настройки цен'!$A$17:$A$24,0))),'Настройки цен'!$B$5)) -> 0 | AF12: =IF(AC12="","",ROUND(AC12*(1+AE12)/'Настройки цен'!$B$6,0)*'Настройки цен'!$B$6) | AG12: =IF(OR(AC12="",H12=""),"",H12/AC12-1)
B13: Ремкомплект шкворня моста Хантер | D13: Уаз | E13: Подвеска | H13: 15000 | I13: 2 | K13: =I13-J13 -> 2 | L13: =K13*H13 -> 30000 | M13: =IF(A13="","",H13*J13) | N13: =IF(A13="","",G13*J13) | O13: =IF(A13="","",M13-N13) | AB13: =SUMPRODUCT(--(R13:AA13>0),'Настройки цен'!$B$12:$K$12) -> 0 | AC13: =IF(AB13=0,"",SUMPRODUCT(R13:AA13,'Настройки цен'!$B$11:$K$11,'Настройки цен'!$B$12:$K$12)/AB13) | AE13: =IF(AD13<>"",AD13,IFERROR(IF(INDEX('Настройки цен'!$B$17:$B$24,MATCH(E13,'Настройки цен'!$A$17:$A$24,0))="",'Настройки цен'!$B$5,INDEX('Настройки цен'!$B$17:$B$24,MATCH(E13,'Настройки цен'!$A$17:$A$24,0))),'Настройки цен'!$B$5)) -> 0 | AF13: =IF(AC13="","",ROUND(AC13*(1+AE13)/'Настройки цен'!$B$6,0)*'Настройки цен'!$B$6) | AG13: =IF(OR(AC13="",H13=""),"",H13/AC13-1)
A14: 42x68x16.4 | B14: Сальник хвостовика раздаточной коробки | D14: УАЗ | E14: Подвеска | H14: 1500 | I14: 13 | K14: =I14-J14 -> 13 | L14: =K14*H14 -> 19500 | M14: =IF(A14="","",H14*J14) -> 0 | N14: =IF(A14="","",G14*J14) -> 0 | O14: =IF(A14="","",M14-N14) -> 0 | Q14: 42x68x16.4 | AB14: =SUMPRODUCT(--(R14:AA14>0),'Настройки цен'!$B$12:$K$12) -> 0 | AC14: =IF(AB14=0,"",SUMPRODUCT(R14:AA14,'Настройки цен'!$B$11:$K$11,'Настройки цен'!$B$12:$K$12)/AB14) | AE14: =IF(AD14<>"",AD14,IFERROR(IF(INDEX('Настройки цен'!$B$17:$B$24,MATCH(E14,'Настройки цен'!$A$17:$A$24,0))="",'Настройки цен'!$B$5,INDEX('Настройки цен'!$B$17:$B$24,MATCH(E14,'Настройки цен'!$A$17:$A$24,0))),'Настройки цен'!$B$5)) -> 0 | AF14: =IF(AC14="","",ROUND(AC14*(1+AE14)/'Настройки цен'!$B$6,0)*'Настройки цен'!$B$6) | AG14: =IF(OR(AC14="",H14=""),"",H14/AC14-1)
A15: 38x56x10 | B15: Сальник в кпп | D15: ГАЗ | E15: Подвеска | H15: 1000 | I15: 30 | K15: =I15-J15 -> 30 | L15: =K15*H15 -> 30000 | M15: =IF(A15="","",H15*J15) -> 0 | N15: =IF(A15="","",G15*J15) -> 0 | O15: =IF(A15="","",M15-N15) -> 0 | Q15: 38x56x10 | AB15: =SUMPRODUCT(--(R15:AA15>0),'Настройки цен'!$B$12:$K$12) -> 0 | AC15: =IF(AB15=0,"",SUMPRODUCT(R15:AA15,'Настройки цен'!$B$11:$K$11,'Настройки цен'!$B$12:$K$12)/AB15) | AE15: =IF(AD15<>"",AD15,IFERROR(IF(INDEX('Настройки цен'!$B$17:$B$24,MATCH(E15,'Настройки цен'!$A$17:$A$24,0))="",'Настройки цен'!$B$5,INDEX('Настройки цен'!$B$17:$B$24,MATCH(E15,'Настройки цен'!$A$17:$A$24,0))),'Настройки цен'!$B$5)) -> 0 | AF15: =IF(AC15="","",ROUND(AC15*(1+AE15)/'Настройки цен'!$B$6,0)*'Настройки цен'!$B$6) | AG15: =IF(OR(AC15="",H15=""),"",H15/AC15-1)
A16: 40x56x7.5 | B16: Сальник коленвала | D16: ВАЗ | E16: Двигатель | H16: 2000 | I16: 10 | K16: =I16-J16 -> 10 | L16: =K16*H16 -> 20000 | M16: =IF(A16="","",H16*J16) -> 0 | N16: =IF(A16="","",G16*J16) -> 0 | O16: =IF(A16="","",M16-N16) -> 0 | Q16: 40x56x7.5 | AB16: =SUMPRODUCT(--(R16:AA16>0),'Настройки цен'!$B$12:$K$12) -> 0 | AC16: =IF(AB16=0,"",SUMPRODUCT(R16:AA16,'Настройки цен'!$B$11:$K$11,'Настройки цен'!$B$12:$K$12)/AB16) | AE16: =IF(AD16<>"",AD16,IFERROR(IF(INDEX('Настройки цен'!$B$17:$B$24,MATCH(E16,'Настройки цен'!$A$17:$A$24,0))="",'Настройки цен'!$B$5,INDEX('Настройки цен'!$B$17:$B$24,MATCH(E16,'Настройки цен'!$A$17:$A$24,0))),'Настройки цен'!$B$5)) -> 0 | AF16: =IF(AC16="","",ROUND(AC16*(1+AE16)/'Настройки цен'!$B$6,0)*'Настройки цен'!$B$6) | AG16: =IF(OR(AC16="",H16=""),"",H16/AC16-1)
A17: 80x100x10 | B17: Сальник коленвала | D17: ВАЗ | E17: Двигатель | H17: 4000 | I17: 40 | K17: =I17-J17 -> 40 | L17: =K17*H17 -> 160000 | M17: =IF(A17="","",H17*J17) -> 0 | N17: =IF(A17="","",G17*J17) -> 0 | O17: =IF(A17="","",M17-N17) -> 0 | Q17: 80x100x10 | AB17: =SUMPRODUCT(--(R17:AA17>0),'Настройки цен'!$B$12:$K$12) -> 0 | AC17: =IF(AB17=0,"",SUMPRODUCT(R17:AA17,'Настройки цен'!$B$11:$K$11,'Настройки цен'!$B$12:$K$12)/AB17) | AE17: =IF(AD17<>"",AD17,IFERROR(IF(INDEX('Настройки цен'!$B$17:$B$24,MATCH(E17,'Настройки цен'!$A$17:$A$24,0))="",'Настройки цен'!$B$5,INDEX('Настройки цен'!$B$17:$B$24,MATCH(E17,'Настройки цен'!$A$17:$A$24,0))),'Настройки цен'!$B$5)) -> 0 | AF17: =IF(AC17="","",ROUND(AC17*(1+AE17)/'Настройки цен'!$B$6,0)*'Настройки цен'!$B$6) | AG17: =IF(OR(AC17="",H17=""),"",H17/AC17-1)
A18: 21212202025 | B18: Крестовина нива | D18: ВАЗ | E18: Подвеска | H18: 4000 | I18: 1 | K18: =I18-J18 -> 1 | L18: =K18*H18 -> 4000 | M18: =IF(A18="","",H18*J18) -> 0 | N18: =IF(A18="","",G18*J18) -> 0 | O18: =IF(A18="","",M18-N18) -> 0 | Q18: 21212202025 | AB18: =SUMPRODUCT(--(R18:AA18>0),'Настройки цен'!$B$12:$K$12) -> 0 | AC18: =IF(AB18=0,"",SUMPRODUCT(R18:AA18,'Настройки цен'!$B$11:$K$11,'Настройки цен'!$B$12:$K$12)/AB18) | AE18: =IF(AD18<>"",AD18,IFERROR(IF(INDEX('Настройки цен'!$B$17:$B$24,MATCH(E18,'Настройки цен'!$A$17:$A$24,0))="",'Настройки цен'!$B$5,INDEX('Настройки цен'!$B$17:$B$24,MATCH(E18,'Настройки цен'!$A$17:$A$24,0))),'Настройки цен'!$B$5)) -> 0 | AF18: =IF(AC18="","",ROUND(AC18*(1+AE18)/'Настройки цен'!$B$6,0)*'Настройки цен'!$B$6) | AG18: =IF(OR(AC18="",H18=""),"",H18/AC18-1)
A19: 21052202025 | B19: Крестовина Жигули | D19: ВАЗ | E19: Подвеска | H19: 3000 | I19: 16 | K19: =I19-J19 -> 16 | L19: =K19*H19 -> 48000 | M19: =IF(A19="","",H19*J19) -> 0 | N19: =IF(A19="","",G19*J19) -> 0 | O19: =IF(A19="","",M19-N19) -> 0 | Q19: 21052202025 | AB19: =SUMPRODUCT(--(R19:AA19>0),'Настройки цен'!$B$12:$K$12) -> 0 | AC19: =IF(AB19=0,"",SUMPRODUCT(R19:AA19,'Настройки цен'!$B$11:$K$11,'Настройки цен'!$B$12:$K$12)/AB19) | AE19: =IF(AD19<>"",AD19,IFERROR(IF(INDEX('Настройки цен'!$B$17:$B$24,MATCH(E19,'Настройки цен'!$A$17:$A$24,0))="",'Настройки цен'!$B$5,INDEX('Настройки цен'!$B$17:$B$24,MATCH(E19,'Настройки цен'!$A$17:$A$24,0))),'Настройки цен'!$B$5)) -> 0 | AF19: =IF(AC19="","",ROUND(AC19*(1+AE19)/'Настройки цен'!$B$6,0)*'Настройки цен'!$B$6) | AG19: =IF(OR(AC19="",H19=""),"",H19/AC19-1)
A20: 469003501041496 | B20: Тормозной цилиндр передний левый | D20: УАЗ | E20: Тормоза | H20: 5000 | I20: 13 | K20: =I20-J20 -> 13 | L20: =K20*H20 -> 65000 | M20: =IF(A20="","",H20*J20) -> 0 | N20: =IF(A20="","",G20*J20) -> 0 | O20: =IF(A20="","",M20-N20) -> 0 | Q20: 469003501041496 | AB20: =SUMPRODUCT(--(R20:AA20>0),'Настройки цен'!$B$12:$K$12) -> 0 | AC20: =IF(AB20=0,"",SUMPRODUCT(R20:AA20,'Настройки цен'!$B$11:$K$11,'Настройки цен'!$B$12:$K$12)/AB20) | AE20: =IF(AD20<>"",AD20,IFERROR(IF(INDEX('Настройки цен'!$B$17:$B$24,MATCH(E20,'Настройки цен'!$A$17:$A$24,0))="",'Настройки цен'!$B$5,INDEX('Настройки цен'!$B$17:$B$24,MATCH(E20,'Настройки цен'!$A$17:$A$24,0))),'Настройки цен'!$B$5)) -> 0 | AF20: =IF(AC20="","",ROUND(AC20*(1+AE20)/'Настройки цен'!$B$6,0)*'Настройки цен'!$B$6) | AG20: =IF(OR(AC20="",H20=""),"",H20/AC20-1)
A21: 469003501040496 | B21: Тормозной цилиндр передний правый | D21: Уаз | E21: Тормоза | H21: 5000 | I21: 4 | K21: =I21-J21 -> 4 | L21: =K21*H21 -> 20000 | M21: =IF(A21="","",H21*J21) -> 0 | N21: =IF(A21="","",G21*J21) -> 0 | O21: =IF(A21="","",M21-N21) -> 0 | Q21: 469003501040496 | AB21: =SUMPRODUCT(--(R21:AA21>0),'Настройки цен'!$B$12:$K$12) -> 0 | AC21: =IF(AB21=0,"",SUMPRODUCT(R21:AA21,'Настройки цен'!$B$11:$K$11,'Настройки цен'!$B$12:$K$12)/AB21) | AE21: =IF(AD21<>"",AD21,IFERROR(IF(INDEX('Настройки цен'!$B$17:$B$24,MATCH(E21,'Настройки цен'!$A$17:$A$24,0))="",'Настройки цен'!$B$5,INDEX('Настройки цен'!$B$17:$B$24,MATCH(E21,'Настройки цен'!$A$17:$A$24,0))),'Настройки цен'!$B$5)) -> 0 | AF21: =IF(AC21="","",ROUND(AC21*(1+AE21)/'Настройки цен'!$B$6,0)*'Настройки цен'!$B$6) | AG21: =IF(OR(AC21="",H21=""),"",H21/AC21-1)
B22: Шаровая опора поворотного кулака | D22: УАЗ | E22: Подвеска | H22: 50000 | I22: 5 | K22: =I22-J22 -> 5 | L22: =K22*H22 -> 250000 | M22: =IF(A22="","",H22*J22) | N22: =IF(A22="","",G22*J22) | O22: =IF(A22="","",M22-N22) | AB22: =SUMPRODUCT(--(R22:AA22>0),'Настройки цен'!$B$12:$K$12) -> 0 | AC22: =IF(AB22=0,"",SUMPRODUCT(R22:AA22,'Настройки цен'!$B$11:$K$11,'Настройки цен'!$B$12:$K$12)/AB22) | AE22: =IF(AD22<>"",AD22,IFERROR(IF(INDEX('Настройки цен'!$B$17:$B$24,MATCH(E22,'Настройки цен'!$A$17:$A$24,0))="",'Настройки цен'!$B$5,INDEX('Настройки цен'!$B$17:$B$24,MATCH(E22,'Настройки цен'!$A$17:$A$24,0))),'Настройки цен'!$B$5)) -> 0 | AF22: =IF(AC22="","",ROUND(AC22*(1+AE22)/'Настройки цен'!$B$6,0)*'Настройки цен'!$B$6) | AG22: =IF(OR(AC22="",H22=""),"",H22/AC22-1)
A23: 4171002060 | B23: Передняя крышка блока цилиндров | D23: УАЗ/ГАЗ | E23: Двигатель | H23: 20000 | I23: 3 | K23: =I23-J23 -> 3 | L23: =K23*H23 -> 60000 | M23: =IF(A23="","",H23*J23) -> 0 | N23: =IF(A23="","",G23*J23) -> 0 | O23: =IF(A23="","",M23-N23) -> 0 | Q23: 4171002060 | AB23: =SUMPRODUCT(--(R23:AA23>0),'Настройки цен'!$B$12:$K$12) -> 0 | AC23: =IF(AB23=0,"",SUMPRODUCT(R23:AA23,'Настройки цен'!$B$11:$K$11,'Настройки цен'!$B$12:$K$12)/AB23) | AE23: =IF(AD23<>"",AD23,IFERROR(IF(INDEX('Настройки цен'!$B$17:$B$24,MATCH(E23,'Настройки цен'!$A$17:$A$24,0))="",'Настройки цен'!$B$5,INDEX('Настройки цен'!$B$17:$B$24,MATCH(E23,'Настройки цен'!$A$17:$A$24,0))),'Настройки цен'!$B$5)) -> 0 | AF23: =IF(AC23="","",ROUND(AC23*(1+AE23)/'Настройки цен'!$B$6,0)*'Настройки цен'!$B$6) | AG23: =IF(OR(AC23="",H23=""),"",H23/AC23-1)
A24: 45x85x24.75 | B24: Подшипник ступицы | D24: УАЗ | E24: Подвеска | H24: 5000 | I24: 17 | K24: =I24-J24 -> 17 | L24: =K24*H24 -> 85000 | M24: =IF(A24="","",H24*J24) -> 0 | N24: =IF(A24="","",G24*J24) -> 0 | O24: =IF(A24="","",M24-N24) -> 0 | Q24: 45x85x24.75 | AB24: =SUMPRODUCT(--(R24:AA24>0),'Настройки цен'!$B$12:$K$12) -> 0 | AC24: =IF(AB24=0,"",SUMPRODUCT(R24:AA24,'Настройки цен'!$B$11:$K$11,'Настройки цен'!$B$12:$K$12)/AB24) | AE24: =IF(AD24<>"",AD24,IFERROR(IF(INDEX('Настройки цен'!$B$17:$B$24,MATCH(E24,'Настройки цен'!$A$17:$A$24,0))="",'Настройки цен'!$B$5,INDEX('Настройки цен'!$B$17:$B$24,MATCH(E24,'Настройки цен'!$A$17:$A$24,0))),'Настройки цен'!$B$5)) -> 0 | AF24: =IF(AC24="","",ROUND(AC24*(1+AE24)/'Настройки цен'!$B$6,0)*'Настройки цен'!$B$6) | AG24: =IF(OR(AC24="",H24=""),"",H24/AC24-1)
A25: 50x90x24.75 | B25: Подшипник дифференциала | D25: Уаз | E25: Подвеска | H25: 6000 | I25: 2 | K25: =I25-J25 -> 2 | L25: =K25*H25 -> 12000 | M25: =IF(A25="","",H25*J25) -> 0 | N25: =IF(A25="","",G25*J25) -> 0 | O25: =IF(A25="","",M25-N25) -> 0 | Q25: 50x90x24.75 | AB25: =SUMPRODUCT(--(R25:AA25>0),'Настройки цен'!$B$12:$K$12) -> 0 | AC25: =IF(AB25=0,"",SUMPRODUCT(R25:AA25,'Настройки цен'!$B$11:$K$11,'Настройки цен'!$B$12:$K$12)/AB25) | AE25: =IF(AD25<>"",AD25,IFERROR(IF(INDEX('Настройки цен'!$B$17:$B$24,MATCH(E25,'Настройки цен'!$A$17:$A$24,0))="",'Настройки цен'!$B$5,INDEX('Настройки цен'!$B$17:$B$24,MATCH(E25,'Настройки цен'!$A$17:$A$24,0))),'Настройки цен'!$B$5)) -> 0 | AF25: =IF(AC25="","",ROUND(AC25*(1+AE25)/'Настройки цен'!$B$6,0)*'Настройки цен'!$B$6) | AG25: =IF(OR(AC25="",H25=""),"",H25/AC25-1)
B26: Хабы Noname (комплект) | D26: УАЗ | E26: Подвеска | H26: 40000 | I26: 4 | K26: =I26-J26 -> 4 | L26: =K26*H26 -> 160000 | M26: =IF(A26="","",H26*J26) | N26: =IF(A26="","",G26*J26) | O26: =IF(A26="","",M26-N26) | AB26: =SUMPRODUCT(--(R26:AA26>0),'Настройки цен'!$B$12:$K$12) -> 0 | AC26: =IF(AB26=0,"",SUMPRODUCT(R26:AA26,'Настройки цен'!$B$11:$K$11,'Настройки цен'!$B$12:$K$12)/AB26) | AE26: =IF(AD26<>"",AD26,IFERROR(IF(INDEX('Настройки цен'!$B$17:$B$24,MATCH(E26,'Настройки цен'!$A$17:$A$24,0))="",'Настройки цен'!$B$5,INDEX('Настройки цен'!$B$17:$B$24,MATCH(E26,'Настройки цен'!$A$17:$A$24,0))),'Настройки цен'!$B$5)) -> 0 | AF26: =IF(AC26="","",ROUND(AC26*(1+AE26)/'Настройки цен'!$B$6,0)*'Настройки цен'!$B$6) | AG26: =IF(OR(AC26="",H26=""),"",H26/AC26-1)
A27: 4511701120 | B27: Муфта КПП 3-4 передачи со ступицей | D27: УАЗ | E27: Подвеска | H27: 12000 | I27: 1 | K27: =I27-J27 -> 1 | L27: =K27*H27 -> 12000 | M27: =IF(A27="","",H27*J27) -> 0 | N27: =IF(A27="","",G27*J27) -> 0 | O27: =IF(A27="","",M27-N27) -> 0 | Q27: 4511701120 | AB27: =SUMPRODUCT(--(R27:AA27>0),'Настройки цен'!$B$12:$K$12) -> 0 | AC27: =IF(AB27=0,"",SUMPRODUCT(R27:AA27,'Настройки цен'!$B$11:$K$11,'Настройки цен'!$B$12:$K$12)/AB27) | AE27: =IF(AD27<>"",AD27,IFERROR(IF(INDEX('Настройки цен'!$B$17:$B$24,MATCH(E27,'Настройки цен'!$A$17:$A$24,0))="",'Настройки цен'!$B$5,INDEX('Настройки цен'!$B$17:$B$24,MATCH(E27,'Настройки цен'!$A$17:$A$24,0))),'Настройки цен'!$B$5)) -> 0 | AF27: =IF(AC27="","",ROUND(AC27*(1+AE27)/'Настройки цен'!$B$6,0)*'Настройки цен'!$B$6) | AG27: =IF(OR(AC27="",H27=""),"",H27/AC27-1)
A28: 4691701127 | B28: Шестерня 2й передачи н/о | D28: УАЗ | E28: Подвеска | H28: 15000 | I28: 4 | K28: =I28-J28 -> 4 | L28: =K28*H28 -> 60000 | M28: =IF(A28="","",H28*J28) -> 0 | N28: =IF(A28="","",G28*J28) -> 0 | O28: =IF(A28="","",M28-N28) -> 0 | Q28: 4691701127 | AB28: =SUMPRODUCT(--(R28:AA28>0),'Настройки цен'!$B$12:$K$12) -> 0 | AC28: =IF(AB28=0,"",SUMPRODUCT(R28:AA28,'Настройки цен'!$B$11:$K$11,'Настройки цен'!$B$12:$K$12)/AB28) | AE28: =IF(AD28<>"",AD28,IFERROR(IF(INDEX('Настройки цен'!$B$17:$B$24,MATCH(E28,'Настройки цен'!$A$17:$A$24,0))="",'Настройки цен'!$B$5,INDEX('Настройки цен'!$B$17:$B$24,MATCH(E28,'Настройки цен'!$A$17:$A$24,0))),'Настройки цен'!$B$5)) -> 0 | AF28: =IF(AC28="","",ROUND(AC28*(1+AE28)/'Настройки цен'!$B$6,0)*'Настройки цен'!$B$6) | AG28: =IF(OR(AC28="",H28=""),"",H28/AC28-1)
A29: 45150170111200 | B29: Шестерня 1й передачи | D29: УАЗ | E29: Подвеска | H29: 8000 | I29: 2 | K29: =I29-J29 -> 2 | L29: =K29*H29 -> 16000 | M29: =IF(A29="","",H29*J29) -> 0 | N29: =IF(A29="","",G29*J29) -> 0 | O29: =IF(A29="","",M29-N29) -> 0 | Q29: 45150170111200 | AB29: =SUMPRODUCT(--(R29:AA29>0),'Настройки цен'!$B$12:$K$12) -> 0 | AC29: =IF(AB29=0,"",SUMPRODUCT(R29:AA29,'Настройки цен'!$B$11:$K$11,'Настройки цен'!$B$12:$K$12)/AB29) | AE29: =IF(AD29<>"",AD29,IFERROR(IF(INDEX('Настройки цен'!$B$17:$B$24,MATCH(E29,'Настройки цен'!$A$17:$A$24,0))="",'Настройки цен'!$B$5,INDEX('Настройки цен'!$B$17:$B$24,MATCH(E29,'Настройки цен'!$A$17:$A$24,0))),'Настройки цен'!$B$5)) -> 0 | AF29: =IF(AC29="","",ROUND(AC29*(1+AE29)/'Настройки цен'!$B$6,0)*'Настройки цен'!$B$6) | AG29: =IF(OR(AC29="",H29=""),"",H29/AC29-1)
A30: 61121168 | B30: Шайба стопорная переднего колеса | D30: УАЗ | E30: Подвеска | H30: 500 | I30: 5 | K30: =I30-J30 -> 5 | L30: =K30*H30 -> 2500 | M30: =IF(A30="","",H30*J30) -> 0 | N30: =IF(A30="","",G30*J30) -> 0 | O30: =IF(A30="","",M30-N30) -> 0 | Q30: 61121168 | AB30: =SUMPRODUCT(--(R30:AA30>0),'Настройки цен'!$B$12:$K$12) -> 0 | AC30: =IF(AB30=0,"",SUMPRODUCT(R30:AA30,'Настройки цен'!$B$11:$K$11,'Настройки цен'!$B$12:$K$12)/AB30) | AE30: =IF(AD30<>"",AD30,IFERROR(IF(INDEX('Настройки цен'!$B$17:$B$24,MATCH(E30,'Настройки цен'!$A$17:$A$24,0))="",'Настройки цен'!$B$5,INDEX('Настройки цен'!$B$17:$B$24,MATCH(E30,'Настройки цен'!$A$17:$A$24,0))),'Настройки цен'!$B$5)) -> 0 | AF30: =IF(AC30="","",ROUND(AC30*(1+AE30)/'Настройки цен'!$B$6,0)*'Настройки цен'!$B$6) | AG30: =IF(OR(AC30="",H30=""),"",H30/AC30-1)
A31: 3207 | B31: Подшипник вторичного вала КПП | D31: УАЗ | E31: Подвеска | H31: 5000 | I31: 4 | K31: =I31-J31 -> 4 | L31: =K31*H31 -> 20000 | M31: =IF(A31="","",H31*J31) -> 0 | N31: =IF(A31="","",G31*J31) -> 0 | O31: =IF(A31="","",M31-N31) -> 0 | Q31: 3207 | AB31: =SUMPRODUCT(--(R31:AA31>0),'Настройки цен'!$B$12:$K$12) -> 0 | AC31: =IF(AB31=0,"",SUMPRODUCT(R31:AA31,'Настройки цен'!$B$11:$K$11,'Настройки цен'!$B$12:$K$12)/AB31) | AE31: =IF(AD31<>"",AD31,IFERROR(IF(INDEX('Настройки цен'!$B$17:$B$24,MATCH(E31,'Настройки цен'!$A$17:$A$24,0))="",'Настройки цен'!$B$5,INDEX('Настройки цен'!$B$17:$B$24,MATCH(E31,'Настройки цен'!$A$17:$A$24,0))),'Настройки цен'!$B$5)) -> 0 | AF31: =IF(AC31="","",ROUND(AC31*(1+AE31)/'Настройки цен'!$B$6,0)*'Настройки цен'!$B$6) | AG31: =IF(OR(AC31="",H31=""),"",H31/AC31-1)
A32: 4691701134 | B32: Муфта переключения 1-2й передачи | D32: УАЗ | E32: Подвеска | H32: 25000 | I32: 1 | K32: =I32-J32 -> 1 | L32: =K32*H32 -> 25000 | M32: =IF(A32="","",H32*J32) -> 0 | N32: =IF(A32="","",G32*J32) -> 0 | O32: =IF(A32="","",M32-N32) -> 0 | Q32: 4691701134 | AB32: =SUMPRODUCT(--(R32:AA32>0),'Настройки цен'!$B$12:$K$12) -> 0 | AC32: =IF(AB32=0,"",SUMPRODUCT(R32:AA32,'Настройки цен'!$B$11:$K$11,'Настройки цен'!$B$12:$K$12)/AB32) | AE32: =IF(AD32<>"",AD32,IFERROR(IF(INDEX('Настройки цен'!$B$17:$B$24,MATCH(E32,'Настройки цен'!$A$17:$A$24,0))="",'Настройки цен'!$B$5,INDEX('Настройки цен'!$B$17:$B$24,MATCH(E32,'Настройки цен'!$A$17:$A$24,0))),'Настройки цен'!$B$5)) -> 0 | AF32: =IF(AC32="","",ROUND(AC32*(1+AE32)/'Настройки цен'!$B$6,0)*'Настройки цен'!$B$6) | AG32: =IF(OR(AC32="",H32=""),"",H32/AC32-1)
A33: 4691701116 | B33: Муфта синхронизатора 3-4 й передачи | D33: УАЗ | E33: Подвеска | H33: 25000 | I33: 1 | K33: =I33-J33 -> 1 | L33: =K33*H33 -> 25000 | M33: =IF(A33="","",H33*J33) -> 0 | N33: =IF(A33="","",G33*J33) -> 0 | O33: =IF(A33="","",M33-N33) -> 0 | Q33: 4691701116 | AB33: =SUMPRODUCT(--(R33:AA33>0),'Настройки цен'!$B$12:$K$12) -> 0 | AC33: =IF(AB33=0,"",SUMPRODUCT(R33:AA33,'Настройки цен'!$B$11:$K$11,'Настройки цен'!$B$12:$K$12)/AB33) | AE33: =IF(AD33<>"",AD33,IFERROR(IF(INDEX('Настройки цен'!$B$17:$B$24,MATCH(E33,'Настройки цен'!$A$17:$A$24,0))="",'Настройки цен'!$B$5,INDEX('Настройки цен'!$B$17:$B$24,MATCH(E33,'Настройки цен'!$A$17:$A$24,0))),'Настройки цен'!$B$5)) -> 0 | AF33: =IF(AC33="","",ROUND(AC33*(1+AE33)/'Настройки цен'!$B$6,0)*'Настройки цен'!$B$6) | AG33: =IF(OR(AC33="",H33=""),"",H33/AC33-1)
A34: 3102220102522 | B34: Крестовина карданного вала | D34: УАЗ/ГАЗ | E34: Подвеска | H34: 10000 | I34: 28 | K34: =I34-J34 -> 28 | L34: =K34*H34 -> 280000 | M34: =IF(A34="","",H34*J34) -> 0 | N34: =IF(A34="","",G34*J34) -> 0 | O34: =IF(A34="","",M34-N34) -> 0 | Q34: 3102220102522 | V34: 664 | AB34: =SUMPRODUCT(--(R34:AA34>0),'Настройки цен'!$B$12:$K$12) -> 1 | AC34: =IF(AB34=0,"",SUMPRODUCT(R34:AA34,'Настройки цен'!$B$11:$K$11,'Настройки цен'!$B$12:$K$12)/AB34) -> 3519.2 | AE34: =IF(AD34<>"",AD34,IFERROR(IF(INDEX('Настройки цен'!$B$17:$B$24,MATCH(E34,'Настройки цен'!$A$17:$A$24,0))="",'Настройки цен'!$B$5,INDEX('Настройки цен'!$B$17:$B$24,MATCH(E34,'Настройки цен'!$A$17:$A$24,0))),'Настройки цен'!$B$5)) -> 0 | AF34: =IF(AC34="","",ROUND(AC34*(1+AE34)/'Настройки цен'!$B$6,0)*'Настройки цен'!$B$6) -> 3500 | AG34: =IF(OR(AC34="",H34=""),"",H34/AC34-1) -> 1.8415549 | AH34: detaliuaz.ru: крестовина кардана УАЗ/ГАЗ d30 «Автомагнат» 664 ₽ (аналог, не оригинал). Наша цена 10 000 ₸ — сильно выше рынка РФ.
A35: 452002304112 | B35: муфта скользящая фланца | D35: УАЗ | E35: Подвеска | H35: 13000 | I35: 5 | K35: =I35-J35 -> 5 | L35: =K35*H35 -> 65000 | M35: =IF(A35="","",H35*J35) -> 0 | N35: =IF(A35="","",G35*J35) -> 0 | O35: =IF(A35="","",M35-N35) -> 0 | Q35: 452002304112 | AB35: =SUMPRODUCT(--(R35:AA35>0),'Настройки цен'!$B$12:$K$12) -> 0 | AC35: =IF(AB35=0,"",SUMPRODUCT(R35:AA35,'Настройки цен'!$B$11:$K$11,'Настройки цен'!$B$12:$K$12)/AB35) | AE35: =IF(AD35<>"",AD35,IFERROR(IF(INDEX('Настройки цен'!$B$17:$B$24,MATCH(E35,'Настройки цен'!$A$17:$A$24,0))="",'Настройки цен'!$B$5,INDEX('Настройки цен'!$B$17:$B$24,MATCH(E35,'Настройки цен'!$A$17:$A$24,0))),'Настройки цен'!$B$5)) -> 0 | AF35: =IF(AC35="","",ROUND(AC35*(1+AE35)/'Настройки цен'!$B$6,0)*'Настройки цен'!$B$6) | AG35: =IF(OR(AC35="",H35=""),"",H35/AC35-1)
A36: 315120230440003 | B36: Хаб Noname (1шт) | D36: УАЗ | E36: Подвеска | H36: 20000 | I36: 2 | K36: =I36-J36 -> 2 | L36: =K36*H36 -> 40000 | M36: =IF(A36="","",H36*J36) -> 0 | N36: =IF(A36="","",G36*J36) -> 0 | O36: =IF(A36="","",M36-N36) -> 0 | Q36: 315120230440003 | AB36: =SUMPRODUCT(--(R36:AA36>0),'Настройки цен'!$B$12:$K$12) -> 0 | AC36: =IF(AB36=0,"",SUMPRODUCT(R36:AA36,'Настройки цен'!$B$11:$K$11,'Настройки цен'!$B$12:$K$12)/AB36) | AE36: =IF(AD36<>"",AD36,IFERROR(IF(INDEX('Настройки цен'!$B$17:$B$24,MATCH(E36,'Настройки цен'!$A$17:$A$24,0))="",'Настройки цен'!$B$5,INDEX('Настройки цен'!$B$17:$B$24,MATCH(E36,'Настройки цен'!$A$17:$A$24,0))),'Настройки цен'!$B$5)) -> 0 | AF36: =IF(AC36="","",ROUND(AC36*(1+AE36)/'Настройки цен'!$B$6,0)*'Настройки цен'!$B$6) | AG36: =IF(OR(AC36="",H36=""),"",H36/AC36-1)
A37: 374100380203400 | B37: Шестерня привода спидометра 16-17 зубов | D37: Уаз | E37: Другое | H37: 7000 | I37: 5 | K37: =I37-J37 -> 5 | L37: =K37*H37 -> 35000 | M37: =IF(A37="","",H37*J37) -> 0 | N37: =IF(A37="","",G37*J37) -> 0 | O37: =IF(A37="","",M37-N37) -> 0 | Q37: 374100380203400 | AB37: =SUMPRODUCT(--(R37:AA37>0),'Настройки цен'!$B$12:$K$12) -> 0 | AC37: =IF(AB37=0,"",SUMPRODUCT(R37:AA37,'Настройки цен'!$B$11:$K$11,'Настройки цен'!$B$12:$K$12)/AB37) | AE37: =IF(AD37<>"",AD37,IFERROR(IF(INDEX('Настройки цен'!$B$17:$B$24,MATCH(E37,'Настройки цен'!$A$17:$A$24,0))="",'Настройки цен'!$B$5,INDEX('Настройки цен'!$B$17:$B$24,MATCH(E37,'Настройки цен'!$A$17:$A$24,0))),'Настройки цен'!$B$5)) -> 0 | AF37: =IF(AC37="","",ROUND(AC37*(1+AE37)/'Настройки цен'!$B$6,0)*'Настройки цен'!$B$6) | AG37: =IF(OR(AC37="",H37=""),"",H37/AC37-1)
A38: 33073802034 | B38: Шестерня привода спидометра 21 зуб | D38: ГАЗ | E38: Другое | H38: 10000 | I38: 5 | K38: =I38-J38 -> 5 | L38: =K38*H38 -> 50000 | M38: =IF(A38="","",H38*J38) -> 0 | N38: =IF(A38="","",G38*J38) -> 0 | O38: =IF(A38="","",M38-N38) -> 0 | Q38: 33073802034 | AB38: =SUMPRODUCT(--(R38:AA38>0),'Настройки цен'!$B$12:$K$12) -> 0 | AC38: =IF(AB38=0,"",SUMPRODUCT(R38:AA38,'Настройки цен'!$B$11:$K$11,'Настройки цен'!$B$12:$K$12)/AB38) | AE38: =IF(AD38<>"",AD38,IFERROR(IF(INDEX('Настройки цен'!$B$17:$B$24,MATCH(E38,'Настройки цен'!$A$17:$A$24,0))="",'Настройки цен'!$B$5,INDEX('Настройки цен'!$B$17:$B$24,MATCH(E38,'Настройки цен'!$A$17:$A$24,0))),'Настройки цен'!$B$5)) -> 0 | AF38: =IF(AC38="","",ROUND(AC38*(1+AE38)/'Настройки цен'!$B$6,0)*'Настройки цен'!$B$6) | AG38: =IF(OR(AC38="",H38=""),"",H38/AC38-1)
A39: 374100170125000 | B39: Вал промежуточный | D39: УАЗ | E39: Подвеска | H39: 22000 | I39: 1 | K39: =I39-J39 -> 1 | L39: =K39*H39 -> 22000 | M39: =IF(A39="","",H39*J39) -> 0 | N39: =IF(A39="","",G39*J39) -> 0 | O39: =IF(A39="","",M39-N39) -> 0 | Q39: 374100170125000 | AB39: =SUMPRODUCT(--(R39:AA39>0),'Настройки цен'!$B$12:$K$12) -> 0 | AC39: =IF(AB39=0,"",SUMPRODUCT(R39:AA39,'Настройки цен'!$B$11:$K$11,'Настройки цен'!$B$12:$K$12)/AB39) | AE39: =IF(AD39<>"",AD39,IFERROR(IF(INDEX('Настройки цен'!$B$17:$B$24,MATCH(E39,'Настройки цен'!$A$17:$A$24,0))="",'Настройки цен'!$B$5,INDEX('Настройки цен'!$B$17:$B$24,MATCH(E39,'Настройки цен'!$A$17:$A$24,0))),'Настройки цен'!$B$5)) -> 0 | AF39: =IF(AC39="","",ROUND(AC39*(1+AE39)/'Настройки цен'!$B$6,0)*'Настройки цен'!$B$6) | AG39: =IF(OR(AC39="",H39=""),"",H39/AC39-1)
A40: 42x68x10x15.5 | B40: Сальник хвостовика и РК | D40: УАЗ | E40: Подвеска | H40: 1500 | I40: 17 | K40: =I40-J40 -> 17 | L40: =K40*H40 -> 25500 | M40: =IF(A40="","",H40*J40) -> 0 | N40: =IF(A40="","",G40*J40) -> 0 | O40: =IF(A40="","",M40-N40) -> 0 | Q40: 42x68x10x15.5 | AB40: =SUMPRODUCT(--(R40:AA40>0),'Настройки цен'!$B$12:$K$12) -> 0 | AC40: =IF(AB40=0,"",SUMPRODUCT(R40:AA40,'Настройки цен'!$B$11:$K$11,'Настройки цен'!$B$12:$K$12)/AB40) | AE40: =IF(AD40<>"",AD40,IFERROR(IF(INDEX('Настройки цен'!$B$17:$B$24,MATCH(E40,'Настройки цен'!$A$17:$A$24,0))="",'Настройки цен'!$B$5,INDEX('Настройки цен'!$B$17:$B$24,MATCH(E40,'Настройки цен'!$A$17:$A$24,0))),'Настройки цен'!$B$5)) -> 0 | AF40: =IF(AC40="","",ROUND(AC40*(1+AE40)/'Настройки цен'!$B$6,0)*'Настройки цен'!$B$6) | AG40: =IF(OR(AC40="",H40=""),"",H40/AC40-1)
...

Sheet Настройки цен
A1: НАСТРОЙКИ ЦЕНООБРАЗОВАНИЯ
A3: Курс рубля, ₸ за 1 ₽ | B3: 5.3
A4: Надбавка к российским ценам (доставка, растаможка), % | B4: 0
A5: Общая наценка на среднюю цену рынка, % | B5: 0
A6: Округлять цену до, ₸ | B6: 100
A9: Источник | B9: autogur73.ru | C9: chipdip.kz | D9: uaz.store | E9: metalpart.ru | F9: detaliuaz.ru | G9: vta-gaz.ru | H9: spectuninguaz.ru | I9: 4uaz.ru | J9: Kaspi | K9: Ozon
A10: Валюта (RUB / KZT) | B10: RUB | C10: KZT | D10: RUB | E10: RUB | F10: RUB | G10: RUB | H10: RUB | I10: RUB | J10: KZT | K10: KZT
A11: Курс пересчёта в ₸ (авто) | B11: =IF(B10="RUB",$B$3*(1+$B$4),1) -> 5.3 | C11: =IF(C10="RUB",$B$3*(1+$B$4),1) -> 1 | D11: =IF(D10="RUB",$B$3*(1+$B$4),1) -> 5.3 | E11: =IF(E10="RUB",$B$3*(1+$B$4),1) -> 5.3 | F11: =IF(F10="RUB",$B$3*(1+$B$4),1) -> 5.3 | G11: =IF(G10="RUB",$B$3*(1+$B$4),1) -> 5.3 | H11: =IF(H10="RUB",$B$3*(1+$B$4),1) -> 5.3 | I11: =IF(I10="RUB",$B$3*(1+$B$4),1) -> 5.3 | ... K11: =IF(K10="RUB",$B$3*(1+$B$4),1) -> 1
A12: Учитывать в средней (1 — да, 0 — нет) | B12: 1 | C12: 1 | D12: 1 | E12: 1 | F12: 1 | G12: 1 | H12: 1 | I12: 1 | J12: 1 | K12: 1
A15: Наценка по категориям (пусто = общая)
A16: Категория | B16: Наценка, %
A17: Двигатель
A18: Другое
A19: Кузов
A20: Подвеска
A21: Расходники
A22: Тормоза
A23: Фильтры
A24: Электрика
A26: Жёлтые ячейки — для изменения. Синий шрифт — вводимые значения, чёрный — формулы.

Sheet Сводка
A1: СВОДКА ПО СКЛАДУ И ПРОДАЖАМ
A2: Показатель | B2: Значение
A3: Всего позиций | B3: =COUNTIF(Запчасти!B2:B501,"<>") -> 278
A4: Всего единиц на остатке | B4: =SUM(Запчасти!K2:K501) -> 2846
A5: Всего товаров на сумму | B5: =Запчасти!L502 -> 13926450 | C5: =B5/450 -> 30947.667 | D5: Это в Долларах
A6: Выручка | B6: =SUM(Запчасти!M2:M501) -> 0
A7: Себестоимость проданного | B7: =SUM(Запчасти!N2:N501) -> 0
A8: Прибыль | B8: =SUM(Запчасти!O2:O501) -> 0

Sheet Как пользоваться
A1: КРАТКАЯ ИНСТРУКЦИЯ | B1: Вносите каждую запчасть отдельной строкой на вкладке «Запчасти».
A2: 2 | B2: Заполняйте артикул, название, производителя, автомобиль, цены и количество.
A3: 3 | B3: В колонке «Продано» указывайте, сколько единиц уже продано.
A4: 4 | B4: «Остаток», «Выручка», «Себестоимость проданного» и «Прибыль» считаются автоматически.
A5: 5 | B5: Вкладка «Сводка» показывает общие показатели по складу.
A6: 6 | B6: Файл можно загрузить в Google Таблицы и работать с ним с телефона и ноутбука.
