Workbook

Sheet Запчасти
A1: Артикул | B1: Наименование | C1: Производитель | D1: Подходит к авто | E1: Категория | F1: Дата поступления | G1: Закупочная цена | H1: Цена продажи | I1: Поступило | J1: Продано | K1: Остаток | L1: Всего на сумму | M1: Выручка | N1: Себестоимость проданного | O1: Прибыль | P1: Комментарий | AI1: ID
B2: шланг Тормозной длинный | D2: УАЗ | E2: Тормоза | H2: 3000 | I2: 22 | J2: 1 | K2: =I2-J2 -> 21 | L2: =K2*H2 -> 63000 | M2: =IF(A2="","",H2*J2) | N2: =IF(A2="","",G2*J2) | O2: =IF(A2="","",M2-N2) | AI2: 1
A3: Р4-3706 020 | B3: Бегунок трамблёра | D3: ГАЗ | E3: Двигатель | H3: 1000 | I3: 6 | K3: =I3-J3 -> 6 | L3: =K3*H3 -> 6000 | M3: =IF(A3="","",H3*J3) -> 0 | N3: =IF(A3="","",G3*J3) -> 0 | O3: =IF(A3="","",M3-N3) -> 0 | AI3: 2
B4: Блок управления отопителем | D4: Газель | E4: Другое | H4: 5000 | I4: 1 | K4: =I4-J4 -> 1 | L4: =K4*H4 -> 5000 | M4: =IF(A4="","",H4*J4) | N4: =IF(A4="","",G4*J4) | O4: =IF(A4="","",M4-N4) | AI4: 3
A5: 521701080 | B5: Блок шестерен заднего хода | D5: ГАЗ | E5: Подвеска | H5: 17000 | I5: 7 | K5: =I5-J5 -> 7 | L5: =K5*H5 -> 119000 | M5: =IF(A5="","",H5*J5) -> 0 | N5: =IF(A5="","",G5*J5) -> 0 | O5: =IF(A5="","",M5-N5) -> 0 | AI5: 4
B6: Блок шестерен КПП | D6: ГАЗ | E6: Подвеска | H6: 50000 | I6: 7 | K6: =I6-J6 -> 7 | L6: =K6*H6 -> 350000 | M6: =IF(A6="","",H6*J6) | N6: =IF(A6="","",G6*J6) | O6: =IF(A6="","",M6-N6) | AI6: 5
A7: 53121701306 | B7: Блок шестерен КПП | D7: ГАЗ 53 | E7: Подвеска | H7: 90000 | I7: 3 | K7: =I7-J7 -> 3 | L7: =K7*H7 -> 270000 | M7: =IF(A7="","",H7*J7) -> 0 | N7: =IF(A7="","",G7*J7) -> 0 | O7: =IF(A7="","",M7-N7) -> 0 | AI7: 6
B8: Болт генератора | D8: УАЗ/ ГАЗ | E8: Другое | H8: 300 | I8: 25 | K8: =I8-J8 -> 25 | L8: =K8*H8 -> 7500 | M8: =IF(A8="","",H8*J8) | N8: =IF(A8="","",G8*J8) | O8: =IF(A8="","",M8-N8) | AI8: 7
B9: Болт главной пары | D9: УАЗ | E9: Подвеска | H9: 200 | I9: 105 | K9: =I9-J9 -> 105 | L9: =K9*H9 -> 21000 | M9: =IF(A9="","",H9*J9) | N9: =IF(A9="","",G9*J9) | O9: =IF(A9="","",M9-N9) | AI9: 8
B10: Болт кардана с гайкой, шайбой | D10: Уаз | E10: Подвеска | H10: 300 | I10: 42 | K10: =I10-J10 -> 42 | L10: =K10*H10 -> 12600 | M10: =IF(A10="","",H10*J10) | N10: =IF(A10="","",G10*J10) | O10: =IF(A10="","",M10-N10) | AI10: 9
A11: M10x1x35 | B11: Болт картера моста | D11: УАЗ | E11: Другое | H11: 300 | I11: 180 | K11: =I11-J11 -> 180 | L11: =K11*H11 -> 54000 | M11: =IF(A11="","",H11*J11) -> 0 | N11: =IF(A11="","",G11*J11) -> 0 | O11: =IF(A11="","",M11-N11) -> 0 | AI11: 10
A12: M10x25 | B12: Болт крепления полуоси | D12: УАЗ | E12: Другое | H12: 300 | I12: 25 | K12: =I12-J12 -> 25 | L12: =K12*H12 -> 7500 | M12: =IF(A12="","",H12*J12) -> 0 | N12: =IF(A12="","",G12*J12) -> 0 | O12: =IF(A12="","",M12-N12) -> 0 | AI12: 11
A13: 66-1007075-02 | B13: Болт с гайкой для регулировки карамысла | D13: УАЗ/ ГАЗ | E13: Двигатель | H13: 500 | I13: 32 | K13: =I13-J13 -> 32 | L13: =K13*H13 -> 16000 | M13: =IF(A13="","",H13*J13) -> 0 | N13: =IF(A13="","",G13*J13) -> 0 | O13: =IF(A13="","",M13-N13) -> 0 | AI13: 12
A14: 3151350106810 | B14: Болт эксцентриковый для регулировки передних колодок | D14: УАЗ | E14: Тормоза | H14: 1500 | I14: 19 | K14: =I14-J14 -> 19 | L14: =K14*H14 -> 28500 | M14: =IF(A14="","",H14*J14) -> 0 | N14: =IF(A14="","",G14*J14) -> 0 | O14: =IF(A14="","",M14-N14) -> 0 | AI14: 13
B15: Болт m10x1.25x33.5 | D15: УАЗ/ ГАЗ | E15: Другое | H15: 300 | I15: 18 | K15: =I15-J15 -> 18 | L15: =K15*H15 -> 5400 | M15: =IF(A15="","",H15*J15) | N15: =IF(A15="","",G15*J15) | O15: =IF(A15="","",M15-N15) | AI15: 14
A16: 452001701105 | B16: Вал вторичный | D16: УАЗ | E16: Подвеска | H16: 15000 | I16: 2 | K16: =I16-J16 -> 2 | L16: =K16*H16 -> 30000 | M16: =IF(A16="","",H16*J16) -> 0 | N16: =IF(A16="","",G16*J16) -> 0 | O16: =IF(A16="","",M16-N16) -> 0 | AI16: 15
A17: 3741170215095 | B17: Вал муфты механизма переключения передач | D17: УАЗ | E17: Подвеска | H17: 3000 | I17: 4 | K17: =I17-J17 -> 4 | L17: =K17*H17 -> 12000 | M17: =IF(A17="","",H17*J17) -> 0 | N17: =IF(A17="","",G17*J17) -> 0 | O17: =IF(A17="","",M17-N17) -> 0 | AI17: 16
A18: 31621802054 | B18: Вал привода заднего моста РК | D18: УАЗ | E18: Подвеска | H18: 30000 | I18: 3 | K18: =I18-J18 -> 3 | L18: =K18*H18 -> 90000 | M18: =IF(A18="","",H18*J18) -> 0 | N18: =IF(A18="","",G18*J18) -> 0 | O18: =IF(A18="","",M18-N18) -> 0 | AI18: 17
A19: 316200180211000 | B19: Вал привода переднего моста выходной вал раздатки | D19: УАЗ | E19: Подвеска | H19: 25000 | I19: 2 | K19: =I19-J19 -> 2 | L19: =K19*H19 -> 50000 | M19: =IF(A19="","",H19*J19) -> 0 | N19: =IF(A19="","",G19*J19) -> 0 | O19: =IF(A19="","",M19-N19) -> 0 | AI19: 18
A20: 374100170125000 | B20: Вал промежуточный | D20: УАЗ | E20: Подвеска | H20: 22000 | I20: 1 | K20: =I20-J20 -> 1 | L20: =K20*H20 -> 22000 | M20: =IF(A20="","",H20*J20) -> 0 | N20: =IF(A20="","",G20*J20) -> 0 | O20: =IF(A20="","",M20-N20) -> 0 | AI20: 19
A21: 21А1005125 | B21: Венец маховика | D21: УАЗ/ ГАЗ | E21: Двигатель | H21: 10000 | I21: 7 | K21: =I21-J21 -> 7 | L21: =K21*H21 -> 70000 | M21: =IF(A21="","",H21*J21) -> 0 | N21: =IF(A21="","",G21*J21) -> 0 | O21: =IF(A21="","",M21-N21) -> 0 | AI21: 20
A22: 241308010 | B22: Вентилятор охлаждения | D22: УАЗ/ ГАЗ | E22: Двигатель | H22: 3000 | I22: 1 | K22: =I22-J22 -> 1 | L22: =K22*H22 -> 3000 | M22: =IF(A22="","",H22*J22) -> 0 | N22: =IF(A22="","",G22*J22) -> 0 | O22: =IF(A22="","",M22-N22) -> 0 | AI22: 21
A23: 33021702024 | B23: Вилка КПП | D23: Газель | E23: Подвеска | H23: 8000 | I23: 3 | K23: =I23-J23 -> 3 | L23: =K23*H23 -> 24000 | M23: =IF(A23="","",H23*J23) -> 0 | N23: =IF(A23="","",G23*J23) -> 0 | O23: =IF(A23="","",M23-N23) -> 0 | AI23: 22
A24: 45200170202402 | B24: Вилка КПП 1й-2й передачи с/о | D24: УАЗ | E24: Подвеска | H24: 8000 | I24: 1 | K24: =I24-J24 -> 1 | L24: =K24*H24 -> 8000 | M24: =IF(A24="","",H24*J24) -> 0 | N24: =IF(A24="","",G24*J24) -> 0 | O24: =IF(A24="","",M24-N24) -> 0 | AI24: 23
A25: СТ2303708020 | B25: Вилка стартера | D25: УАЗ/ ГАЗ | E25: Двигатель | H25: 1500 | I25: 4 | K25: =I25-J25 -> 4 | L25: =K25*H25 -> 6000 | M25: =IF(A25="","",H25*J25) -> 0 | N25: =IF(A25="","",G25*J25) -> 0 | O25: =IF(A25="","",M25-N25) -> 0 | AI25: 24
B26: Вилка ШРУСа | D26: УАЗ | E26: Подвеска | H26: 12000 | I26: 3 | K26: =I26-J26 -> 3 | L26: =K26*H26 -> 36000 | M26: =IF(A26="","",H26*J26) | N26: =IF(A26="","",G26*J26) | O26: =IF(A26="","",M26-N26) | AI26: 25
A27: 316000230402312 | B27: Вкладыш шкворня | D27: УАЗ | E27: Подвеска | H27: 1000 | I27: 11 | K27: =I27-J27 -> 11 | L27: =K27*H27 -> 11000 | M27: =IF(A27="","",H27*J27) -> 0 | N27: =IF(A27="","",G27*J27) -> 0 | O27: =IF(A27="","",M27-N27) -> 0 | AI27: 26
A28: 24100010231 | B28: Вкладыши коренные 0.50 | D28: УАЗ/ГАЗ | E28: Двигатель | H28: 10000 | I28: 2 | K28: =I28-J28 -> 2 | L28: =K28*H28 -> 20000 | M28: =IF(A28="","",H28*J28) -> 0 | N28: =IF(A28="","",G28*J28) -> 0 | O28: =IF(A28="","",M28-N28) -> 0 | AI28: 27
A29: 24100010202 | B29: Вкладыши шатунные 0.25 | D29: УАЗ/ГАЗ | E29: Двигатель | H29: 10000 | I29: 3 | K29: =I29-J29 -> 3 | L29: =K29*H29 -> 30000 | M29: =IF(A29="","",H29*J29) -> 0 | N29: =IF(A29="","",G29*J29) -> 0 | O29: =IF(A29="","",M29-N29) -> 0 | AI29: 28
A30: 241000104 | B30: Вкладыши шатунные 0.75 | D30: УАЗ/ГАЗ | E30: Двигатель | H30: 10000 | I30: 1 | K30: =I30-J30 -> 1 | L30: =K30*H30 -> 10000 | M30: =IF(A30="","",H30*J30) -> 0 | N30: =IF(A30="","",G30*J30) -> 0 | O30: =IF(A30="","",M30-N30) -> 0 | AI30: 29
A31: 4691701105 | B31: Вторичный вал | D31: УАЗ | E31: Подвеска | H31: 15000 | I31: 3 | K31: =I31-J31 -> 3 | L31: =K31*H31 -> 45000 | M31: =IF(A31="","",H31*J31) -> 0 | N31: =IF(A31="","",G31*J31) -> 0 | O31: =IF(A31="","",M31-N31) -> 0 | AI31: 30
A32: 53121701101 | B32: Вторичный вал КПП | D32: ГАЗ | E32: Подвеска | H32: 25000 | I32: 6 | K32: =I32-J32 -> 6 | L32: =K32*H32 -> 150000 | M32: =IF(A32="","",H32*J32) -> 0 | N32: =IF(A32="","",G32*J32) -> 0 | O32: =IF(A32="","",M32-N32) -> 0 | AI32: 31
B33: Втулка шатуна | D33: УАЗ/ ГАЗ | E33: Двигатель | H33: 1500 | I33: 11 | K33: =I33-J33 -> 11 | L33: =K33*H33 -> 16500 | M33: =IF(A33="","",H33*J33) | N33: =IF(A33="","",G33*J33) | O33: =IF(A33="","",M33-N33) | AI33: 32
B34: Выключатель массы | D34: ГАЗ 53 | E34: Электрика | H34: 3000 | I34: 3 | K34: =I34-J34 -> 3 | L34: =K34*H34 -> 9000 | M34: =IF(A34="","",H34*J34) | N34: =IF(A34="","",G34*J34) | O34: =IF(A34="","",M34-N34) | AI34: 33
A35: 211009070 | B35: Высоковольтные провода (комплект) | D35: УАЗ/ ГАЗ | E35: Двигатель | H35: 4000 | I35: 7 | K35: =I35-J35 -> 7 | L35: =K35*H35 -> 28000 | M35: =IF(A35="","",H35*J35) -> 0 | N35: =IF(A35="","",G35*J35) -> 0 | O35: =IF(A35="","",M35-N35) -> 0 | AI35: 34
B36: Высоковольтный провод (длинный) | E36: Двигатель | H36: 1000 | I36: 16 | K36: =I36-J36 -> 16 | L36: =K36*H36 -> 16000 | M36: =IF(A36="","",H36*J36) | N36: =IF(A36="","",G36*J36) | O36: =IF(A36="","",M36-N36) | AI36: 35
B37: Высоковольтный провод (короткий) | E37: Двигатель | H37: 500 | I37: 15 | K37: =I37-J37 -> 15 | L37: =K37*H37 -> 7500 | M37: =IF(A37="","",H37*J37) | N37: =IF(A37="","",G37*J37) | O37: =IF(A37="","",M37-N37) | AI37: 36
B38: Гайка колёсная ГАЗ 53 | D38: ГАЗ 53 | E38: Подвеска | H38: 1000 | I38: 6 | K38: =I38-J38 -> 6 | L38: =K38*H38 -> 6000 | M38: =IF(A38="","",H38*J38) | N38: =IF(A38="","",G38*J38) | O38: =IF(A38="","",M38-N38) | AI38: 37
A39: 531601178 | B39: Гайка регулирования лапки сцепления | D39: УАЗ/ ГАЗ | E39: Подвеска | H39: 500 | I39: 105 | K39: =I39-J39 -> 105 | L39: =K39*H39 -> 52500 | M39: =IF(A39="","",H39*J39) -> 0 | N39: =IF(A39="","",G39*J39) -> 0 | O39: =IF(A39="","",M39-N39) -> 0 | AI39: 38
A40: M12x1.25x10 | B40: Гайка стойки стабилизатора | D40: УАЗ | E40: Подвеска | H40: 200 | I40: 214 | K40: =I40-J40 -> 214 | L40: =K40*H40 -> 42800 | M40: =IF(A40="","",H40*J40) -> 0 | N40: =IF(A40="","",G40*J40) -> 0 | O40: =IF(A40="","",M40-N40) -> 0 | AI40: 39
...

Sheet Сводка
A1: СВОДКА ПО СКЛАДУ И ПРОДАЖАМ
A2: Показатель | B2: Значение
A3: Всего позиций | B3: =COUNTIF('Запчасти'!B2:B501,"<>") -> 293
A4: Всего единиц на остатке | B4: =SUM('Запчасти'!K2:K501) -> 3017
A5: Всего товаров на сумму | B5: ='Запчасти'!L503 -> 14297150 | C5: =B5/450 -> 31771.444 | D5: Это в Долларах
A6: Выручка | B6: =SUM('Запчасти'!M2:M501) -> 0
A7: Себестоимость проданного | B7: =SUM('Запчасти'!N2:N501) -> 0
A8: Прибыль | B8: =SUM('Запчасти'!O2:O501) -> 0

Sheet Как пользоваться
A1: КРАТКАЯ ИНСТРУКЦИЯ | B1: Вносите каждую запчасть отдельной строкой на вкладке «Запчасти».
A2: 2 | B2: Заполняйте артикул, название, производителя, автомобиль, цены и количество.
A3: 3 | B3: В колонке «Продано» указывайте, сколько единиц уже продано.
A4: 4 | B4: «Остаток», «Выручка», «Себестоимость проданного» и «Прибыль» считаются автоматически.
A5: 5 | B5: Вкладка «Сводка» показывает общие показатели по складу.
A6: 6 | B6: Файл можно загрузить в Google Таблицы и работать с ним с телефона и ноутбука.

Sheet Заказы
A1: Номер заказа | B1: Дата и время | C1: Телефон покупателя | D1: Позиций | E1: Итого, ₸ | F1: Состав | G1: Состав (читаемо) | H1: Статус | I1: Предложено за заказ, ₸ | J1: Итого по прайсу, ₸ | K1: Комментарий
A2: ШКВ-0001 | B2: 2026-09-21T15:18:51+05:00 | C2: 87476108458 | D2: 1 | E2: 600 | F2: 6x2 | G2: Болт генератора, 2 шт × 300 ₸ = 600 ₸ | H2: новый
A3: ШКВ-0002 | B3: 2026-09-22T15:19:50+05:00 | C3: 87476108458 | D3: 1 | E3: 1000 | F3: 1x1 | G3: Р4-3706 020 — Бегунок трамблёра, 1 шт × 1 000 ₸ = 1 000 ₸ | H3: новый
A4: ШКВ-0003 | B4: 2026-09-23T12:52:32+05:00 | C4: +77476108458 | D4: 3 | E4: 15000 | F4: 241x1; 149x2; 1x3 | G4: Трапеция привода дворников, 1 шт × 6 000 ₸ = 6 000 ₸ 40x80x18 — Подшипник в раздатку 6208, 2 шт × 3 000 ₸ = 6 000 ₸ Р4-3706 020 — Бегунок трамблёра, 3 шт × 1 000 ₸ = 3 000 ₸ | H4: новый | J4: 15000 | K4: чек чек
A5: ШКВ-0004 | B5: 2026-09-23T16:25:38+05:00 | C5: 87476108458 | D5: 1 | E5: 990 | F5: 2x1@300 | G5: Блок управления отопителем, 1 шт × 5 000 ₸ = 5 000 ₸ (предложено: 300 ₸/шт = 300 ₸) | H5: новый | I5: 990 | J5: 5000
